Workbook
Name DeviceTypeEnd: #REF!
Name MRDEnd: #REF!
Name MRDStart: #REF!

Sheet Report
B1: 技術評価結果報告書 | P1: Ver | Q1: FT-＊0000－01D
W2: 0 | X2: 検査時間(h)
B3: チケットNO | L3: 実施時期 | R3: ～ | X3: =IF(W3="","",(HOUR(W3)*60+MINUTE(W3)+SECOND(W3)/60)/60)
B4: 実施部署 | E4: 技術評価課 | L4: 実施者 | W4: ↑ここに時間を入力してください
B5: 実施条件 | D5: ソフトバージョン | G5: =IF(試験項目!K5="","試験項目のソフトVerを自動入力します",試験項目!K5) -> 試験項目のソフトVerを自動入力します
D7: 使用端末 （IMEI)
B8: 実施結果 | D8: =IF(COUNTA(試験項目!$T$4:$T$7)=0,"【"&試験項目!S4&"】自動入力します",IF(試験項目!T4="","【"&試験項目!S4&"】組み合わせ無し","【"&試験項目!S4&"】"&試験項目!T4)) -> 【ｘ回前MR⇒最新MR】自動入力します
D9: =IF(COUNTA(試験項目!$T$4:$T$7)=0,"【"&試験項目!S5&"】自動入力します",IF(試験項目!T5="","【"&試験項目!S5&"】組み合わせ無し","【"&試験項目!S5&"】"&試験項目!T5)) -> 【2回前MR⇒最新MR】自動入力します
D10: =IF(COUNTA(試験項目!$T$4:$T$7)=0,"【"&試験項目!S6&"】自動入力します",IF(試験項目!T6="","【"&試験項目!S6&"】組み合わせ無し","【"&試験項目!S6&"】"&試験項目!T6)) -> 【前回MR⇒最新MR】自動入力します
D11: =IF(COUNTA(試験項目!$T$4:$T$7)=0,"【"&試験項目!S7&"】自動入力します",IF(試験項目!T7="","【"&試験項目!S7&"】組み合わせ無し","【"&試験項目!S7&"】"&試験項目!T7)) -> 【最新MR⇒Dummy】自動入力します
T21: 高橋 味加
T22: 大谷 晴香
T23: 瀧本 寿博
T24: 長谷部 理絵
T25: 鶴巻 直哉
T26: 萩谷 恵理香
T27: 野村 綾治
T28: 髙槻 直樹
T29: 伊東 めぐみ
T30: 本保 可奈子
T31: 増永 詩織
T32: 松井 敏文
... T34: 小野 剛慎

Sheet 試験項目
G2: ※赤字は元項目からの加筆箇所 | M2: ＜試験状況確認＞ | P2: ＜試験時間算出＞ | S2: ＜Redmineから情報入力＞
D3: 項目数 | F3: 49 | J3: モデル名 | M3: 試験数 | N3: =IFERROR(HLOOKUP($K$3,$X$11:$AF$65,52,FALSE),"自動入力します") -> 自動入力します | P3: TTL(Hr) | Q3: =SUM(R12:R46) -> 0 | S3: ＜MR組み合わせ＞ | T3: ＜試験条件＞ | U3: (記入例)
D4: 成功 | F4: =COUNTIF($K$12:$K$46,$D4) -> 0 | J4: MR番号 | M4: 成功 | N4: =IF(COUNTIF($K$12:$K$60, M4)=0, 0, COUNTIF($K$12:$K$60, M4)) -> 0 | S4: ｘ回前MR⇒最新MR
D5: 失敗 | F5: =COUNTIF($K$12:$K$46,$D5) -> 0 | J5: ソフトVer. | M5: 失敗 | N5: =IF(COUNTIF($K$12:$K$60, M5)=0, 0, COUNTIF($K$12:$K$60, M5)) -> 0 | S5: 2回前MR⇒最新MR | U5: 3.191YO.0261.a → 5.212YO.0356.a ( MR19 → MR21 )
D6: 実施しない | F6: =COUNTIF($K$12:$K$46,$D6) -> 0 | J6: 実施者 | M6: 試験不可 | N6: =IF(COUNTIF($K$12:$K$60, M6)=0, 0, COUNTIF($K$12:$K$60, M6)) -> 0 | S6: 前回MR⇒最新MR | U6: 5.203YO.0350.a → 5.212YO.0356.a ( MR20 → MR21 )
D7: 試験不可 | F7: =COUNTIF($K$12:$K$46,$D7) -> 0 | J7: 実施日 | M7: 実施しない | N7: =IF(COUNTIF($K$12:$K$60, M7)=0, 0, COUNTIF($K$12:$K$60, M7)) -> 0 | S7: 最新MR⇒Dummy | U7: 5.212YO.0356.a → 9.212YO.0357.a ( MR21 → dummy )
D8: 合計(失敗以外) | F8: =SUM(F4:F7)-F5 -> 0 | M8: 未実施 | N8: =IFERROR(N3-SUM(N4:N6),0) -> 0
D9: 進捗率(失敗以外) | F9: =F8/F3 -> 0 | M9: =IF(N8<>0,"未記入があります","")
P10: ※CTRL+け | Z10: ＜モデル適用表＞
A11: 試験の目的 | B11: No. | C11: Test ID | D11: Section | E11: Sub-section | F11: Test Title | G11: 前提条件 | H11: 試験手順 | I11: 判定基準 | J11: =IF(K3="","自動入力 (モデル名)",K3) -> 自動入力 (モデル名) | K11: 判定 | L11: 判定2 自動入力 | M11: KC備考 | N11: SB備考 | O11: スクショ | P11: Start | Q11: Stop | R11: Time | S11: MR組合せ | T11: 手順 (EB1190 MR7をベースに作成) ※Qualcommモデルは別シート参照 | U11: 注意事項 | X11: TestNo | Y11: TestIDの試験数 | Z11: EB1190 | AA11: EB1209 | AB11: EB1146 | AC11: EB1155 | AD11: EB1083 | AE11: TEST | AT11: トライアル(EB1146) | AU11: 備考 | AV11: 質問 | AW11: コメント
A12: 最新MR→DummyへのGOTA確認 ※モバイルネットワーク使用 | B12: 1 | C12: OTR-MA-LQC-999.001.001 | D12: FinalTest - Software Update(FOTA/GOTA) | E12: n -> Dummy-delta | F12: Update confirmation | G12: a．最新DLツールでMRソフトにしておく b．ソフトVer.とIMEIのScreenShotを取得する c．Wi-FiをOFFにしておく(モバイルネットワークを使用するため) | H12: (1) ダミーソフトへGOTAする (2) ソフトVer.とIMEIのScreenShotを取得する | I12: ・エラーなくGOTAできること ・OSVの場合は自動的にダウンロードが開始されないこと(ソフトウェア更新の通知＞ユーザー操作後にダウンロードが開始されること) ・GOTA後にソフトVer.が更新したいVer.となっていること ・GOTA前後に取得したソフトVer.とIMEIのScreenShotを提出すること | J12: =IFERROR(HLOOKUP($K$3,$Z$11:$AI$65,$X12+1,FALSE),"自動入力") -> 自動入力 | L12: {=_xlfn.IFS($K$3="","自動入力",COUNTIF(J12,"×")=COUNTA(J12),"試験不可",COUNTIF(J12,"〇")=COUNTA(K12),IF(COUNTIF(K12,"試験不可")=COUNTA(K12),"試験不可",IF(COUNTIF(K12,"失敗")>0,"NG","OK")),TRUE,"")} -> 自動入力 | N12: =IF(COUNTIF(J12,"×")=COUNTA(J12),"機能が無い為。",IF(AND(COUNTIF(J12,"〇")>0,$S$12=""),"ジャンプ可能なソフトが無い為。","")) | O12: 〇 | R12: =Q12-P12 -> 0 | S12: =IF($T$7<>"",$T$7,"") | T12: ＜準備＞ ①ダウンロードツールにて最新MRへFULL_DL ②リブート後、電源オフしてDNANDLoaderでUSB有効化 ※「SUCCESS」表示後に電源オフの場合は電源オンしてください ③待ち受け画面まで設定をして下さい(「待ち受け設定」シート参照） pSIMを入れていると初期設定画面でSIMの選択画面になりますので、上の表示(こちらがpSIM)をデータ通信・通話・SMSで選択してください。 ④GOTA組み合わせ：最新MR⇒Dummy ⑤モバイルネットワーク使用(WiFiオフしてください） ⑥pSIMを優先SIM設定(データ通信、通話、SMS使用） 設定→ネットワークとインターネット→デュアルSIM設定→優先SIMがSIM1になっている事を確認 ＜手順＞ ①GOTA前スクショ 設定→デバイス情報→ビルド番号とIMEI(SIMスロット1と2)のスクショし「No」に合わせて保存(No毎にフォルダを作成して保存してください) ※ビルド番号とIMEIが1画面に入りきらない場合は分けて取得 ②アップデート 設定→システム→システムアップデート→システムアップデート利用可能の画面で【更新内容】のビルド番号がDummyの番号である事を確認→ダウンロードしてインストール→モバイルネットワークを使用をタップ→アップデートが完了するまで暫く待ちます。(10分程度)→今すぐ再起動をタップ ③電源オフとしてDNANDLoaderでUSBデバッグオンを設定 ④GOTA後スクショ 設定→デバイス情報→ビルド番号とIMEI(SIMスロット1と2)のスクショし「No」に合わせて保存(No毎にフォルダを作成して保存してください) ※ビルド番号とIMEIが1画面に入りきらない場合は分けて取得 ⑤GOTA前後の画像をWinMergeで比較して差を確認してください。詳しくは別シートを参照下さい | U12: ＜ツール＞ ①ブタ ②adbtool ③Vysor(スクショとミラキャスト）or adb_capture.bat 【注意事項】 ①アップデートが正常に終了しない場合や、極端に時間が長い場合は松井まで連絡してください。 ②OSVの場合は自動的にダウンロードが開始されない(ソフトウェア更新通知→ユーザー操後にダウンロード開始） ※モデルによって異なりますが、通知エリア(Nortification)に通知されるので、それからユーザー操作でダウンロードする | X12: 1 | Y12: =X12 -> 1 | Z12: 〇 | AA12: 〇 | AB12: 〇 | AD12: 〇 | AE12: 〇 | AT12: ※5.212YO.0356.a → 9.212YO.0357.a ( MR21 → dummy ) ※Wi-FiをOFFにしておく(モバイルネットワークを使用するため) ①MR21へFULL_DL ：3分 ※Kcflashtoolにて最新ソフトへダウンロード ②待ち受け(WiFi無) ：3分 ③スクショ ※設定一部おかしい？ ※どこのスクショ？3枚撮った！ →ビルド番号、IMEI番号(タップで表示)、システムアップデート利用可能画面 ④設定⇒システム⇒システムアップデート ④システムアップデート実施 4G(NR) Dummy：13.31MB ダウンロード：5分 ⑤再起動 ：1分 ⑥Dummy_DL後スクショ →ビルド番号、IMEI番号(タップで表示) ⑦最新MRへ再DL ：3分 ⑧再起動 ：1分 ⑨待ち受け ：3分 ※合計：25分程度 | AU12: 1)DLツールで書き換えします ２）差分作成が完了するとチケットが発行されるのでそれを参考にしてください 例 1917737 | AV12: ・「ダミーソフト」はGOTAでアップデートするソフトと理解していますがあっていますか？ ・GOTAサーバーは北見で操作する事は無いと理解していますが、業務の流れを教えて頂ければと思います。(チケット発行時にご準備されている?) | AW12: ＜ダミーソフト＞ 今回MRで将来的に発生するGOTAが正常に行われる事を確認するために、差分ファイルの大部分をダミーデータとしたソフトになります。
A13: 非課金SIMを使った最新MR→DummyへのGOTA確認 ※モバイルネットワーク使用 | B13: 2 | C13: OTR-MA-LQC-999.001.002 | D13: FinalTest - Software Update(FOTA/GOTA) | E13: n -> Dummy-delta | F13: Non-Charge confirmation (OEM-FOTA) | G13: a．最新MRソフトにしておく b．Wi-FiをOFFにしておく(モバイルネットワークを使用するため) c．下記2種類のSIMを用意する ・SIM-A：非課金確認用SIM(機種に応じてSB、YMのSIMを使用すること) ・SIM-B：上記以外のSIM(機種に応じてSB、YMのSIMを使用すること) d．My Softbank(YM機種はMy Y!mobile)でSIM-Aのデータ使用量を確認する e．GOTAする差分ファイルサイズを確認する(備考へ記載すること) | H13: (d-1) SIM-A(非課金確認用SIM)はいかなる端末からも外して2時間以上経過していること (d-2) PCで、My Softbank(My Y!mobile)のデータ使用量を確認する | I13: 備考にデータ使用量を記載すること | J13: =IFERROR(HLOOKUP($K$3,$Z$11:$AI$65,$X13+1,FALSE),"自動入力") -> 自動入力 | L13: {=_xlfn.IFS($K$3="","自動入力",COUNTIF(J13:J17,"×")=COUNTA(J13:J17),"試験不可",COUNTIF(J13:J17,"〇")=COUNTA(K13:K17)-COUNTIF(J13:J17,"×"),IF(COUNTIF(K13:K17,"試験不可")=COUNTA(K13:K17)-COUNTIF(J13:J17,"×"),"試験不可",IF(COUNTIF(K13:K17,"失敗")>0,"NG","OK")),TRUE,"")} -> 自動入力 | R13: =Q13-P13 -> 0 | S13: =IF($T$7<>"",$T$7,"") | T13: ＜準備＞ ①ダウンロードツールにて最新MRへFULL_DL ②リブート後、電源オフしてDNANDLoaderでUSB有効化 ※「SUCCESS」表示後に電源オフの場合は電源オンしてください ③待ち受け画面まで設定をして下さい(別ワークシート参照） ④GOTA組み合わせ：最新MR⇒Dummy ⑤モバイルネットワーク使用(WiFiオフしてください） ⑥PCで、My Softbank(My Y!mobile)のデータ使用量を事前に確認して備考欄に記録して下さい。 ※データの増加分(使用量)を試験後に備考欄に記入する為、事前の数値を記録します。 ※「非課金SIMサイト」ワークシートにデータ使用量の確認方法を記載しています。 ＜手順＞ ①仕向け先の非課金SIMと通常SIMを用意する | U13: 【注意事項】 ●非課金SIMは端末から外した状態で2時間以上放置してから使用してください。 ●この試験は非課金SIMと通常SIMの２種類を使用します。 ●非課金SIMはSBとYMの２種類があり、モデルの仕向け先のキャリアによって使い分けします。 | X13: =X12+1 -> 2 | Y13: =MAX(X13:X17)-X12 -> 5 | Z13: 〇 | AA13: 〇 | AB13: 〇 | AD13: 〇 | AE13: 〇 | AT13: ※事前確認：SB/YM非課金SIMデータ使用量はアクティベート後でデータ使用量はゼロ ※MySB/MyYMでのデータ量確認方法は別途手順書を参照下さい。 | AU13: 非課金確認用SIMですが、キャリア貸出SIM及び京セラの法人契約のSIMでは個別MDMのデータ量は確認できませんので使用できません。今は個人契約のSIMを使っています。DCJから返却してもらうことも可能ですが、2025年2月は8機種試験予定ですので、すべて京セラでの実施可能かどうがわかりません。端末の初期化は工場出荷時のリセットで実施しています。 | AV13: ・非課金SIMの準備について個人契約のSIMをお使いという事ですので、ご準備頂く事は可能でしょうか？ | AW13: ＜非課金SIM＞ 法人契約では非課金SIMの購入は出来ない為、志賀さん個人でSB/Y!mobileのSIMを購入し、料金については支払い依頼で清算をされているとの事です。非課金SIMの購入について検討が必要になります。 ※My Softbankでデータ使用量の確認を行う為に必要になります。
B14: 3 | G14: f．端末を初期化する(意図せずデータ通信するアプリを排除するため) | H14: (1) SIM-B(非課金でないSIM)を装着する (2) モバイルネットワークを使用し、初期設定を完了させる ※ダウンロード方法によっては、更新SWが自動的にダウンロードされる場合があるため、ホーム画面に遷移後、ダウンロードが開始される前に一時停止すること (3) 初期設定後、バックグラウンド通信が完了するまで10分以上待つ (4) 初期設定後の通信が完了後、設定アプリのモバイルデータ使用量で、使用量が増加したすべてのアプリに対してバックグラウンド通信を無効へ変更する (7の準備1) Chromeアプリを起動し、メニュー＞設定＞ホームページ＞OFF にする (7の準備2) Chromeアプリのタブを全て閉じ、アプリ履歴からChromeを削除する (5) SIM-A(非課金確認用SIM)に差し替える 設定アプリでモバイルデータ使用量(合計)を確認する | I14: 備考にデータ使用量(合計)を記載すること | J14: =IFERROR(HLOOKUP($K$3,$Z$11:$AI$65,$X14+1,FALSE),"自動入力") -> 自動入力 | R14: =Q14-P14 -> 0 | T14: ＜準備＞ ①WiFiオフしている事を確認 ②設定⇒ネットワークとインターネット⇒デュアルSIM設定⇒モバイルデータ・通話・SMSメッセージを全てpSIMに設定する ③Playストア→右上アカウント→アプリとデバイスの管理⇒すべて更新⇒アプリを全て更新してください。 ④10分以上放置する ※設定⇒ネットワークとインターネット⇒SIM⇒pSIM⇒モバイルデータの使用量が増えない状態まで待ちます。 ●バックグラウンド通信無効方法 設定→ネットワークとインターネット→SIM→pSIM→モバイルデータの使用量⇒各アプリを選択⇒バックグラウンドデータをタップし、トグルをオフ(グレイアウト) ⑥Chrome⇒右上「…」→設定⇒ホームページ→トグルオフ(グレイアウト） ⑦Chrome⇒右上の□＋数字をタップ⇒タブを全て閉じる((各々の×をタップ) ⑧ホーム画面⇒下から真ん中までスワイプ→右へスワイプ⇒「すべてクリア」をタップして履歴消去 ⑨非課金SIMへ差し替える ⑩pSIMを選択(通話・データ通信・SMS) ⑪設定→ネットワークとインターネット→SIM→pSIM→モバイルデータの使用量→数字を備考欄に記録 | U14: 【注意事項】 ●ダウンロード方法によっては、更新SWが自動的にダウンロードされる場合があるため、ホーム画面に遷移後、ダウンロードが開始される前に一時停止すること(EB1190は更新されない様です) | X14: =X13+1 -> 3 | Z14: 〇 | AA14: 〇 | AB14: 〇 | AD14: 〇 | AE14: 〇 | AT14: 【注記】 ・SIM-B(非課金では無いSIM＝通常のSIM）を使う事 ・WiFiはオフ設定しておく事 (4)設定→ネットワークとインターネット→SIM→YM/SB→アプリのデータ使用量→数字を記録しておく(今回は382MB) 10分放置する ※バックグランドデータ使用の無効方法 モバイルデータ使用量→アプリ選択→バックグランドデータ→トグルをオフ (各アプリはスクショを取って前後確認をした方が良いかも…) 10分後：387MBであったので、下記の3つのアプリのバックグラウンドをオフ設定 ・Google Play ストア ・Google Play 開発者サービス ・Google ( ７の準備1） Chrome→…→設定→ホームページ→トグルオフ (7の準備2) Chrome→①→全てのChrome履歴を閉じる(×） HOME→■(履歴）→すべてクリア （5）SIM-A（非課金SIM)へ差し替え ※電源入ったままでOK 設定→ネットワークとインターネット→SIM→SB/YM→アプリのデータ使用量→数字を記録(今回は174KB) | AX14: =SUM(#REF!) -> #REF!
B15: 4 | H15: (6) ダミーソフトへGOTAする 差分ファイルサイズを確認する ※10MB未満の場合はMySoftbankで判断できないため、試験方法を問い合わせること | I15: GOTAできること 備考へ差分ファイルサイズを記載すること | J15: =IFERROR(HLOOKUP($K$3,$Z$11:$AI$65,$X15+1,FALSE),"自動入力") -> 自動入力 | R15: =Q15-P15 -> 0 | T15: ＜手順＞ ①設定→システム→システムアップデート→システムアップデート利用可能の画面で【更新内容】のビルド番号がDummyの番号である事を確認⇒ダウンロードしてインストール⇒モバイルネットワークを使用⇒アップデートが完了するまで暫く待ちます。(10分程度)→今すぐ再起動をタップ ②差分ファイルサイズを備考欄に記録 ③電源オフしてDNANDLoaderでUSBデバッグオンを設定 | X15: =X14+1 -> 4 | Z15: 〇 | AA15: 〇 | AB15: 〇 | AD15: 〇 | AE15: 〇 | AT15: 設定→システム→システムアップデート→更新サイズ確認(今回は差分ファイルサイズは13.31MB)→ダウンロードしてインストール→モバイルネットワークを使用→システムアップデート開始 ※時間測定：3分 → 再起動：2分
B16: 5 | H16: (7) GOTA後、ブラウザなどで約50MBのデータ通信を行う (例)Chromeアプリで下記ファイルをダウンロードする <https://srv.negurosu.co.jp/pdf/catalog_taflock.pdf> (短縮URL<https://x.gd/uNF3w>) (8) 設定アプリのモバイルデータ使用量の画面を表示し、使用量を確認する ※スタートフォンやタブレットの場合は、使用量のアプリ一覧画面のScreenShotを取得すること ※全アプリを含むScreenShotを取得すること (可能な場合はキャプチャ範囲を拡大すること) ※必要のない通信が発生しないように手早く行うこと (9) SIMを取り外す(または無効にする) ※My Softbank(My Y!mobile)のデータ使用量は翌日から反映されるため、必要のない通信が発生しないようにするため | I16: 備考にデータ使用量(合計)を記載すること | J16: =IFERROR(HLOOKUP($K$3,$Z$11:$AI$65,$X16+1,FALSE),"自動入力") -> 自動入力 | O16: 〇 | R16: =Q16-P16 -> 0 | T16: ＜手順＞ ①GOTA後に、ブラウザで下記のURLからデータ通信を行う事 (PDFのファイルがダウンロードされます） (例)Chromeアプリで下記ファイルをダウンロードする(adbtool使用） <https://srv.negurosu.co.jp/pdf/catalog_taflock.pdf> (短縮URL<https://x.gd/uNF3w>) 画面右上「…」→「⇓」でダウンロード ②設定⇒ネットワークとインターネット⇒SIM⇒SB/YM選択⇒モバイルデータの使用量⇒数字を備考欄に記入 ③全アプリの使用量のスクリーンショットを取得(1枚に入らない場合は数枚に分けて取得) ④非課金SIMを外す ※確認終了後、出来る限り早く非課金SIMを外して下さい。 ⑤翌日まで待ちます (端末は使いません) ※3時間位でもOKです。 ※WEBでのデータの更新は翌日になりますのでお待ちください。 | X16: =X15+1 -> 5 | Z16: 〇 | AA16: 〇 | AB16: 〇 | AD16: 〇 | AE16: 〇 | AT16: (7)Chrome→https://srv.negurosu.co.jp/pdf/catalog_taflock.pdf→設定→ネットワークとインターネット→SIM→SB/YM→アプリのデータ使用量→数字を記録(今回誤って2個PDFをダウンロードしたので89.7MB）
B17: 6 | H17: (10) 翌日、PCまたは他の端末 で、My Softbank(YM機種はMy Y!mobile)のデータ使用量を確認する ※My Softbankへログインし、使用量の管理＞合計使用量 ※My Y!mobileへログインし、トップページの使用量 | I17: ・GOTAでの通信はデータ使用量が増えていないこと ※データ使用量では、手順7で行った約50MBだけが増えていること 備考にデータ使用量を記載すること | J17: =IFERROR(HLOOKUP($K$3,$Z$11:$AI$65,$X17+1,FALSE),"自動入力") -> 自動入力 | R17: =Q17-P17 -> 0 | T17: ＜手順＞ ①My SoftBank/My YmobileのWebサイト(「非課金SIMサイト」シート参照）からデータ使用量を確認する ②備考欄にデータ使用量を記載する事 | X17: =X16+1 -> 6 | Z17: 〇 | AA17: 〇 | AB17: 〇 | AD17: 〇 | AE17: 〇 | AT17: ※13.31+36.92×2＝87.15MBが理論値ですが、89.7MBは許容範囲？ →判定とはOKで良いですか？(理論値で1回のpdfなら50,23MB) ※データ量は0GB→0.12GBですがこれでOKですか？
A18: 前回MR→最新MRへのGOTA確認 ※モバイルネットワーク使用 | B18: 7 | C18: OTR-MA-LQC-999.002.001 | D18: FinalTest - Software Update(FOTA/GOTA) | E18: n-1 -> n | F18: Update confirmation | G18: a．前回MRソフトにしておく b．ソフトVer.とIMEIのScreenShotを取得する c．Wi-FiをOFFにしておく(モバイルネットワークを使用するため) ※OTR-MA-LQC-999.002.002と同時に試験実施をお願いします | H18: (1) 最新MRソフトへGOTAする (2) ソフトVer.とIMEIのScreenShotを取得する | I18: ・エラーなくGOTAできること ・OSVの場合は自動的にダウンロードが開始されないこと(ソフトウェア更新の通知＞ユーザー操作後にダウンロードが開始されること) ・GOTA後にソフトVer.が更新したいVer.となっていること ・GOTA前後に取得したソフトVer.とIMEIのScreenShotを提出すること | J18: =IFERROR(HLOOKUP($K$3,$Z$11:$AI$65,$X18+1,FALSE),"自動入力") -> 自動入力 | L18: {=_xlfn.IFS($K$3="","自動入力",COUNTIF(J18:J19,"×")=COUNTA(J18:J19),"試験不可",COUNTIF(J18:J19,"〇")=COUNTA(K18:K19),IF(COUNTIF(K18:K19,"試験不可")=COUNTA(K18:K19),"試験不可",IF(COUNTIF(K18:K19,"失敗")>0,"NG","OK")),TRUE,"")} -> 自動入力 | N18: =IF(COUNTIF(J18:J19,"×")=COUNTA(J18:J19),"機能が無い為。",IF(AND(COUNTIF(J18:J19,"〇")>0,$S$18=""),"ジャンプ可能なソフトが無い為。","")) | O18: 〇 | R18: =Q18-P18 -> 0 | S18: =IF($T$6<>"",$T$6,"") | T18: ＜準備＞ ①ダウンロードツールにて前回MRへFULL_DL ②リブート後、電源オフしてDNANDLoaderでUSB有効化 ※「SUCCESS」表示後に電源オフの場合は電源オンしてください ③待ち受け画面まで設定をして下さい(「待ち受け設定」シート参照） pSIMを入れていると初期設定画面でSIMの選択画面になりますので、上の表示(こちらがpSIM)をデータ通信・通話・SMSで選択してください。 ④GOTA組み合わせ：前回MR⇒最新MR ⑤モバイルネットワーク使用(WiFiオフしてください） ⑥pSIMを優先SIM設定(データ通信、通話、SMS使用） 設定→ネットワークとインターネット→デュアルSIM設定→優先SIMがSIM1になっている事を確認 ⑦アプリを最新にします。 Playストア→右上アカウントアイコンタップ→アプリとデバイスの管理→アップデート利用可能の「すべて更新」タップ→「詳細を表示」→全てのアプリが更新されるのを暫く待ちます ⑧＋メッセージの初期設定をしておいて下さい。 ＜手順＞ ①GOTA前スクショ 設定→デバイス情報→IMEI1/2とビルド番号 ※1枚に入らない時は2枚に分ける ②GOTA前にNo8～No17の設定と確認を行う ③アップデート 設定→システム→システムアップデート→システムアップデート利用可能の画面で【更新内容】のビルド番号が最新MRの番号である事を確認→ダウンロードしてインストール→モバイルネットワークを使用をタップ→アップデートが完了するまで暫く待ちます。(10分程度)→今すぐ再起動をタップ ④電源オフしてDNANDLoaderでUSBデバッグオンを設定 ⑤GOTA後スクショ 設定→デバイス情報→IMEI1/2とビルド番号 ※1枚に入らない時は2枚に分ける ⑥GOTA前後の画像をWinMergeで比較して差を確認してください。詳しくは別シートを参照下さい ⑦GOTA後のNo8 ～No17の確認を行って下さい | X18: =X17+1 -> 7 | Y18: =MAX(X18:X19)-X17 -> 2 | Z18: 〇 | AA18: 〇 | AB18: 〇 | AD18: 〇 | AE18: 〇 | AT18: ※5.203YO.0350.a → 5.212YO.0356.a ( MR20 → MR21 ) ※WiFi接続無 ※DL後はアプリを最新版に更新しておいてください(メールが古いと送受信できません）（20分程度） ①前回MRへ再DL：3分 ②再起動：1分 ③初期設定：3分 ※以下の設定を先ずは行う。 ④MR20⇒MR21へアップデート ： 4Gで実施 ：135MB ：6分 ④再起動 ：2分
B19: 8 | H19: (3) GOTA後、音声発信、音声着信、SMS送信、SMS受信、データ通信(ブラウザでWebサイトを表示するなど)を確認する | I19: ・GOTA後、データ通信が正常に動作することを確認すること ・音声発信、音声着信、SMS送信、SMS受信に問題がないこと | J19: =IFERROR(HLOOKUP($K$3,$Z$11:$AI$65,$X19+1,FALSE),"自動入力") -> 自動入力 | R19: =Q19-P19 -> 0 | T19: ＜手順＞ ●音声通話 試験機→対抗機、対抗機→試験機へ発信して通話確認 ●SMS送受信 ＋メッセージアプリで、試験機⇔対抗機にテキストデータ、画像(例えばカメラで取得した画像)の送受信を行う ※GOTA後にテキストデータと画像が消えていない事を確認 ●データ通信 Chrome⇒アカウント選択が聞かれた場合は設定したアカウントを選択⇒サイト検索が正常に行える事を確認(タップして画面遷移する事を確認 | X19: =X18+1 -> 8 | Z19: 〇 | AA19: 〇 | AB19: 〇 | AD19: 〇 | AE19: 〇 | AT19: ※GOTA後に確認する | AX19: =SUM(#REF!) -> #REF!
B20: 9 | C20: OTR-MA-LQC-999.002.002 | D20: FinalTest - Software Update(FOTA/GOTA) | E20: n-1 -> n | F20: User data retention verification : Data saved in storage/application. | G20: a．「OTR-MA-LQC-999.002.001」と同時に実施すること (1) GOTA前に、下記のデータを用意し、使用したデータを試験結果に記録 すること ※各データは複数個を用意すること ・電話帳：入力可能なフィールドをすべて入力すること ・画像(カメラ撮影、ダウンロード) ・LINEのトーク履歴 ・メール：送信SMS、受信SMS、送信MMS、受信MMS | H20: (2) 最新MRソフトへGOTAする (3) GOTA後、手順1で用意したデータが保持されているか確認する | I20: ・GOTA後、用意したデータが保持されていること | J20: =IFERROR(HLOOKUP($K$3,$Z$11:$AI$65,$X20+1,FALSE),"自動入力") -> 自動入力 | L20: {=_xlfn.IFS($K$3="","自動入力",COUNTIF(J20,"×")=COUNTA(J20),"試験不可",COUNTIF(J20,"〇")=COUNTA(K20),IF(COUNTIF(K20,"試験不可")=COUNTA(K20),"試験不可",IF(COUNTIF(K20,"失敗")>0,"NG","OK")),TRUE,"")} -> 自動入力 | N20: =IF(COUNTIF(J20,"×")=COUNTA(J20),"機能が無い為。",IF(AND(COUNTIF(J20,"〇")>0,$S$18=""),"ジャンプ可能なソフトが無い為。","")) | R20: =Q20-P20 -> 0 | T20: ＜手順＞ ※各データは2個以上用意する ※GOTA後は動作確認は不要で、電話帳・画像・LINEトーク・SMSが消えていない事を確認してください。 ●電話帳登録 「電話帳登録」ワークシート参照 ●画像(カメラ撮影、ダウンロード) ・カメラで2枚以上撮影 フォトアプリで画像確認 ・ダウンロード ブラウザ(Chrome)⇒適当なサイトに飛ぶ⇒「画像」をタップ(上の方)⇒画像をロングタップして「画像をダウンロード」 Filesアプリで画像を確認 ●LINEトーク ・【LINEトーク設定方法】でアプリを設定 ・対抗機とラインメッセージ(テキスト、画像)の送受信実施(2回以上） ●メール(プラスメッセージ） No8と同じなので実施不要です | U20: 【LINEトーク設定方法】 ①PlayストアからLINEをインストール ②「新規登録」⇒「次へ」⇒許可⇒認証を行ってくださいで自分の電話番号を確認⇒「⇒」⇒「OK」⇒認証番号を確認⇒「許可」⇒「いいえ、ちがいます」⇒「次へ」⇒「アカウントを新規作成⇒アカウントを新規登録で名前を登録(例：試験機）⇒「⇒」⇒パスワードを登録(例：QAkitami123123）⇒「⇒」⇒友達追加設定のチェックボックスを全て外す⇒「⇒」⇒年齢確認「あとで」⇒「同意する」⇒「OK」⇒「アプリの使用時のみ」⇒「許可」⇒「閉じる」(バッテリー…のポップアップ）⇒友達…のポップアップ「キャンセル」⇒「設定に移動→「許可」⇒対抗機と試験機の友達追加をしてください。 | X20: =X19+1 -> 9 | Y20: =MAX(X20)-X19 -> 1 | Z20: 〇 | AA20: 〇 | AB20: 〇 | AD20: 〇 | AE20: 〇 | AT20: ①設定：1時間(アプリ更新に時間がかかる) ・電話帳入力：1件追加 ・画像 カメラは本体へ(SD無)、ダウンロード(WEBから画像をロングタップでダウンロード)⇒確認はFiles⇒ダウンロードで確認 ・LINEトーク履歴 ①PlayStoreからラインアプリダウンロード＆インストール ②lineを設定しトーク履歴を1件、送受信する ③SMSでテキストと画像を送受信する ※対抗機はSOFTBANK端末 ※SMSアプリは更新をしておく。 ⇒Playストア⇒左上⇒アプリとデバイスの管理⇒アップデート⇒全て更新 (試験機・対抗機共に実施する事) | AV20: ・手順1とはどれを差しますか？ | AW20: ＜複数個のデータ＞ SBから特に指定は無い為、データ量としては規定はないので、FOTA/GOTA後でデータが消えていない事を確認する。
B21: 10 | C21: OTR-MA-LQC-999.002.004 | D21: FinalTest - Software Update(FOTA/GOTA) | E21: n-1 -> n | F21: User data retention verification : Screen lock/Biometric authentication setting | G21: a．「OTR-MA-LQC-999.002.001」と同時に実施すること (1) GOTA前に下記を設定する ・画面ロック：パターン、PIN、パスワードのいずれか(備考へ記載すること) ・生体認証：指紋認証 (対応機種のみ) ・生体認証：顔認証 (対応機種のみ) | H21: (2) 最新MRソフトへGOTAする (3) GOTA後、設定アプリを起動し、手順1で設定したものが保持されているか確認する | I21: ・GOTA後、設定したものが保持されていること | J21: =IFERROR(HLOOKUP($K$3,$Z$11:$AI$65,$X21+1,FALSE),"自動入力") -> 自動入力 | L21: {=_xlfn.IFS($K$3="","自動入力",COUNTIF(J21:J24,"×")=COUNTA(J21:J24),"試験不可",COUNTIF(J21:J24,"〇")=COUNTA(K21:K24),IF(COUNTIF(K21:K24,"試験不可")=COUNTA(K21:K24),"試験不可",IF(COUNTIF(K21:K24,"失敗")>0,"NG","OK")),TRUE,"")} -> 自動入力 | N21: =IF(COUNTIF(J21:J24,"×")=COUNTA(J21:J24),"機能が無い為。",IF(AND(COUNTIF(J21:J24,"〇")>0,$S$18=""),"ジャンプ可能なソフトが無い為。","")) | R21: =Q21-P21 -> 0 | T21: ＜手順＞ ※GOTA後は、画面ロック・生体認証設定が保持されている事を動作確認してください。(No11～13を実施) ●画面ロック ※パターン、PIN、パスワードの何れかを備考欄へ記載する事 【注記】パターンの場合は「Ｚ」、 パスワードの場合は「１２３４」 設定⇒セキュリティとプライバシー⇒画面ロックを設定⇒例：パターン⇒Ｚ⇒次へ⇒Ｚ⇒確認⇒完了 ●生体認証(顔認証) 設定⇒セキュリティとプライバシー⇒デバイスのロック解除⇒顔認証と指紋認証によるロック解除⇒Z⇒同意する⇒スタート⇒カメラ起動⇒完了 ●生体認証(指紋認証) 設定⇒セキュリティとプライバシー⇒デバイスのロック解除⇒顔認証と指紋認証によるロック解除⇒Z⇒指紋⇒もっと見る⇒同意する⇒センサーを指でタッチ⇒20回タッチ⇒完了 | U21: 【注意】 ●生体認証はカメラが無い場合や、指紋認証の機能が無い場合がありますので、その時は実施しなくても良いです。 | X21: =X20+1 -> 10 | Y21: =MAX(X21:X24)-X20 -> 4 | Z21: 〇 | AA21: 〇 | AB21: 〇 | AD21: 〇 | AE21: 〇 | AT21: ①設定→セキュリティとプライバシー⇒各種ロックを設定 ・画面ロック パターン(Ｚパターン） ・顔認証セットアップ ・指紋の設定セットアップ ※5分
B22: 11 | H22: (4) ロック画面に切り替え、手順(1)で設定した画面ロックパターン、PIN、またはパスワードの認識により、ロックを解除する | I22: ・(4)で、解除のパターン、PIN、パスワードの入力により、画面ロックを解除できること | J22: =IFERROR(HLOOKUP($K$3,$Z$11:$AI$65,$X22+1,FALSE),"自動入力") -> 自動入力 | R22: =Q22-P22 -> 0 | T22: ＜手順＞ ①省電力画面(黒画面) ②電源キー単押し ③画面タップ ④パターンロック画面で「Z」入力 ⑤待ち受け画面へ遷移する事 ※顔が端末正面に来ない様に操作してください。(顔認証で解除される) | X22: =X21+1 -> 11 | Z22: 〇 | AA22: 〇 | AB22: 〇 | AD22: 〇 | AE22: 〇 | AT22: ※GOTA後に確認する
B23: 12 | H23: (5) ロック画面へ戻り、手順(1)で設定した指紋認証または顔認証 でロックを解除する | I23: ・(5)で、指紋認証と顔認証 により、画面ロックを解除できること | J23: =IFERROR(HLOOKUP($K$3,$Z$11:$AI$65,$X23+1,FALSE),"自動入力") -> 自動入力 | R23: =Q23-P23 -> 0 | T23: ＜手順＞ ①省電力画面(黒画面) ②電源キー単押し ③ロック画面で指紋登録した指でタップ ④待ち受け画面へ遷移する事 ※顔が端末正面に来ない様に操作してください。(顔認証で解除される) | X23: =X22+1 -> 12 | Z23: × | AA23: 〇 | AB23: 〇 | AD23: × | AE23: × | AT23: ※GOTA後に確認する
B24: 13 | H24: (6) ロック画面へ戻り、手順(1)で設定した顔認証でロックを解除する | I24: ・(6)で、顔認証により、画面ロックを解除できること | J24: =IFERROR(HLOOKUP($K$3,$Z$11:$AI$65,$X24+1,FALSE),"自動入力") -> 自動入力 | R24: =Q24-P24 -> 0 | T24: ＜手順＞ ①省電力画面(黒画面) ②電源キー単押し ③ロック画面で顔を正面へ ④待ち受け画面へ遷移する事 | X24: =X23+1 -> 13 | Z24: 〇 | AA24: 〇 | AB24: 〇 | AD24: 〇 | AE24: 〇 | AT24: ※GOTA後に確認する
B25: 14 | C25: OTR-MA-LQC-999.002.005 | D25: FinalTest - Software Update(FOTA/GOTA) | E25: n-1 -> n | F25: User data retention verification : Emergency Information/Emergency Contact | G25: a．「OTR-MA-LQC-999.002.001」と同時に実施すること b．画面ロックを設定する ※パターン、PIN、パスワードのいずれか c．対向機を用意し、電話帳に対向機の電話番号を登録する (1) GOTA前に下記を設定する ・医療に関する情報：入力可能なフィールドをすべて入力すること ・緊急SOS：緊急SOS、「緊急サービスへの発信」をONに設定し、「通報用の電話番号」へ対向機の電話番号を登録する ・緊急連絡先：対向機の電話番号を追加する | H25: a．「OTR-MA-LQC-999.002.001」と同時に実施すること b．画面ロックを設定する ※パターン、PIN、パスワードのいずれか c．対向機を用意し、電話帳に対向機の電話番号を登録する (1) GOTA前に下記を設定する ・医療に関する情報：入力可能なフィールドをすべて入力すること ・緊急SOS：緊急SOS、「緊急サービスへの発信」をONに設定し、「通報用の電話番号」へ対向機の電話番号を登録する ・緊急連絡先：対向機の電話番号を追加する | I25: ・手順3で、設定したものが保持されていること | J25: =IFERROR(HLOOKUP($K$3,$Z$11:$AI$65,$X25+1,FALSE),"自動入力") -> 自動入力 | L25: {=_xlfn.IFS($K$3="","自動入力",COUNTIF(J25:J27,"×")=COUNTA(J25:J27),"試験不可",COUNTIF(J25:J27,"〇")=COUNTA(K25:K27),IF(COUNTIF(K25:K27,"試験不可")=COUNTA(K25:K27),"試験不可",IF(COUNTIF(K25:K27,"失敗")>0,"NG","OK")),TRUE,"")} -> 自動入力 | N25: =IF(COUNTIF(J25:J27,"×")=COUNTA(J25:J27),"機能が無い為。",IF(AND(COUNTIF(J25:J27,"〇")>0,$S$18=""),"ジャンプ可能なソフトが無い為。","")) | R25: =Q25-P25 -> 0 | T25: ＜手順＞ ※GOTA後は、①の設定が保持されている事と緊急SOSは動作確認(No15 ～16)してください。 ①設定→安全性と緊急情報→医療に関する情報→各情報を全て設定 ②設定→安全性と緊急情報→緊急SOS→緊急通報→緊急通報用の電話番号を110番から必ず変更してください。(例えば自分の業務端末等) ※右記の＜緊急通報用の電話番号設定の初期設定時の手順＞を参照してください。 ※1回変更するとGoogleアカウントに紐づくので以降の変更は要りませんが、試験前に必ず確認してください。 | U25: 【注記】 緊急通報用の電話番号のデフォルトは「１１０」番です。 デフォルト設定を変える前に発信しない様に発信前に必ず電話番号が１１０番では無い事を確認してください。 ＜緊急通報用の電話番号設定の初期設定時の手順＞ 設定→安全性と緊急情報→緊急SOS→緊急通報サービスへの発信→通報用の電話番号→その他→自分の業務端末→完了 | X25: =X24+1 -> 14 | Y25: =MAX(X25:X27)-X24 -> 3 | Z25: 〇 | AA25: × | AB25: 〇 | AD25: 〇 | AE25: 〇 | AT25: ①設定→安全性と緊急情報→医療に関する情報→各情報を全て設定 ②設定→安全性と緊急情報→緊急SOS→緊急通報→緊急通報用の電話番号を110番から必ず変更してください。(例えば自分の業務端末等) ※1回変更するとGoogleアカウントに紐づくので以降の変更は要りませんが、試験前に必ず確認してください。 ＜初期設定＞ 設定→安全性と緊急情報→緊急SOS→緊急通報サービスへの発信→通報用の電話番号→その他→自分の業務端末→完了 | AU25: Androidのバージョンなどで違いがありますが基本設定アプリー緊急情報、緊急通報で設定します。２のSOSは１１９や１１０は使用しません。番号を対抗機に変更して試験実施します。 | AV25: ・手順3とはどれになりますか？ ※以下同じです。
B26: 15 | H26: (4) 電源ボタンをすばやく5回押し、緊急SOSを開始する | I26: ・手順4で、緊急SOSとして登録した対向機へ緊急発信できること | J26: =IFERROR(HLOOKUP($K$3,$Z$11:$AI$65,$X26+1,FALSE),"自動入力") -> 自動入力 | R26: =Q26-P26 -> 0 | T26: ＜手順＞ ※緊急通報用の電話番号が110番から変更されている事を確認する事 ①省電力画面から素早く5回電源キー押下で緊急呼発信画面へ遷移して3秒長押しで発信出来る事を確認 | X26: =X25+1 -> 15 | Z26: 〇 | AA26: × | AB26: 〇 | AD26: 〇 | AE26: 〇 | AT26: 省電力画面から5回電源キー押下で緊急呼発信画面へ遷移して3秒長押しで発信出来る事を確認
B27: 16 | H27: (5) ロック画面から緊急時情報を閲覧し、緊急連絡先へ発信する | I27: ・手順5で、画面ロックを解除することなく、緊急連絡先へ発信できること | J27: =IFERROR(HLOOKUP($K$3,$Z$11:$AI$65,$X27+1,FALSE),"自動入力") -> 自動入力 | R27: =Q27-P27 -> 0 | T27: ＜手順＞ ※緊急通報用の電話番号が110番から変更されている事を確認する事 ①パターンロック画面から素早く5回電源キー押下で緊急呼発信画面へ遷移して3秒長押しで発信出来る事を確認 | X27: =X26+1 -> 16 | Z27: 〇 | AA27: × | AB27: 〇 | AD27: 〇 | AE27: 〇 | AT27: パターンロック画面から5回電源キー押下で緊急呼発信画面へ遷移して3秒長押しで発信出来る事を確認
B28: 17 | C28: OTR-MA-LQC-999.002.006 | D28: FinalTest - Software Update(FOTA/GOTA) | E28: n-1 -> n | F28: User data retention verification : APN | G28: a．「OTR-MA-LQC-999.002.001」と同時に実施すること (1) GOTA前に下記を設定する ・アクセスポイント名：任意のAPNを作成する ・名前/APN/ユーザー名/パスワード/認証タイプ(必要な場合のみ) を設定する (例) ---------- 名前：linemo APN：plus.acs.jp.v6 ユーザー名：lm パスワード：lm 認証タイプ：CHAP | H28: (2) 最新MRへGOTAする (3) GOTA後、手順1で設定したものが保持されているか確認する | I28: ・GOTA後、設定したものが保持されていること | J28: =IFERROR(HLOOKUP($K$3,$Z$11:$AI$65,$X28+1,FALSE),"自動入力") -> 自動入力 | L28: {=_xlfn.IFS($K$3="","自動入力",COUNTIF(J28,"×")=COUNTA(J28),"試験不可",COUNTIF(J28,"〇")=COUNTA(K28),IF(COUNTIF(K28,"試験不可")=COUNTA(K28),"試験不可",IF(COUNTIF(K28,"失敗")>0,"NG","OK")),TRUE,"")} -> 自動入力 | N28: =IF(COUNTIF(J28,"×")=COUNTA(J28),"機能が無い為。",IF(AND(COUNTIF(J28,"〇")>0,$S$18=""),"ジャンプ可能なソフトが無い為。","")) | R28: =Q28-P28 -> 0 | T28: ＜手順＞ ※GOTA後は、設定が保持されている事を確認してください。 ①設定→ネットワークとインターネット⇒SIM⇒pSIM側を選択⇒アクセスポイント⇒「＋」⇒アクセスポイントの編集⇒…⇒保存 ＜AP設定内容＞ ※adbtoolを使ってください 名前：linemo APN：plus.acs.jp.v6 ユーザー名：lm パスワード：lm 認証タイプ：CHAP | X28: =X27+1 -> 17 | Y28: =MAX(X28)-X27 -> 1 | Z28: 〇 | AA28: 〇 | AB28: 〇 | AD28: 〇 | AE28: 〇 | AT28: ①設定→ネットワークとインターネット⇒SIM⇒YM⇒アクセスポイント名⇒APN⇒「＋」⇒アクセスポイントの編集⇒…⇒保存
A29: 技術適合証明書の確認 前回MR→最新MRへのGOTA確認 ※モバイルネットワーク使用しましょう | B29: 18 | C29: OTR-MA-LQC-999.008.001 | D29: FinalTest - Certification | E29: Technical standard conformity/Certification mark | F29: Normality confirmation(After VerUP) | G29: a． 商用と同等の環境を用意する ・端末：商用版と同等のTACを持った端末を使用すること ※使用する機器のTACが、MRD-001732に記載された商用版のTAC(IMEIの先頭8文字)と一致することを確認すること ・ソフトウェア：商用版と同等のソフトVer.を使用すること b．前回MRソフトにしておく c．技術基準適合証明マークが表示された画面のScreenShotを取得する | H29: (1) 最新MRソフトへGOTAする (2) GOTA後にソフトVer.が更新したいVer.となっていることを確認する (3) 技術基準適合証明マークが表示された画面のScreenShotを取得し、GOTA前のScreenShot画像と比較する | I29: ・GOTA前後で技術基準適合証明マーク画面(マーク/数字/文字)が同じであること | J29: =IFERROR(HLOOKUP($K$3,$Z$11:$AI$65,$X29+1,FALSE),"自動入力") -> 自動入力 | L29: {=_xlfn.IFS($K$3="","自動入力",COUNTIF(J29,"×")=COUNTA(J29),"試験不可",COUNTIF(J29,"〇")=COUNTA(K29),IF(COUNTIF(K29,"試験不可")=COUNTA(K29),"試験不可",IF(COUNTIF(K29,"失敗")>0,"NG","OK")),TRUE,"")} -> 自動入力 | N29: =IF(COUNTIF(J29,"×")=COUNTA(J29),"機能が無い為。",IF(AND(COUNTIF(J29,"〇")>0,$S$29=""),"ジャンプ可能なソフトが無い為。","")) | O29: 〇 | R29: =Q29-P29 -> 0 | S29: =IF($T$6<>"",$T$6,"") | T29: ＜準備＞ ①ダウンロードツールにて前回MRへFULL_DL ②リブート後、電源オフしてDNANDLoaderでUSB有効化 ※「SUCCESS」表示後に電源オフの場合は電源オンしてください ③待ち受け画面まで設定をして下さい(「待ち受け設定」シート参照） pSIMを入れていると初期設定画面でSIMの選択画面になりますので、下の表示(こちらがeSIM)をデータ通信・通話・SMSで選択してください。 ④GOTA組み合わせ：前回MR⇒最新MR ⑤モバイルネットワーク使用(WiFiオフしてください） ⑥eSIMを優先SIM設定(データ通信、通話、SMS使用） 設定→ネットワークとインターネット→デュアルSIM設定→優先SIMがSIM2になっている事を確認 ＜手順＞ ①GOTA前スクショ 設定→デバイス情報→技術基準適合証明書 ②アップデート 設定→システム→システムアップデート→システムアップデート利用可能の画面で【更新内容】のビルド番号が最新MRの番号である事を確認→ダウンロードしてインストール→モバイルネットワークを使用をタップ→アップデートが完了するまで暫く待ちます。(10分程度)→今すぐ再起動をタップ ③電源オフとしてDNANDLoaderでUSBデバッグオンを設定 ④GOTA後スクショ 設定→デバイス情報→技術基準適合証明書 ⑤GOTA前後の画像をWinMergeで比較して差を確認してください。詳しくは別シートを参照下さい ※この試験はNo7～17の試験の中で行ってもOKです。 | U29: ＜ツール＞ ①ブタ ②adbtool ③Vysor(スクショとミラキャスト）or adb_capture.bat 【注意事項】 ①アップデートが正常に終了しない場合や、極端に時間が長い場合は松井まで連絡してください。 ②OSVの場合は自動的にダウンロードが開始されない(ソフトウェア更新通知→ユーザー操後にダウンロード開始） ※モデルによって異なりますが、通知エリア(Nortification)に通知されるので、それからユーザー操作でダウンロードする | X29: =X28+1 -> 18 | Y29: =MAX(X29)-X28 -> 1 | Z29: 〇 | AA29: 〇 | AB29: 〇 | AD29: 〇 | AE29: 〇 | AT29: ①設定→デバイス情報→技術基準適合証明
A30: ｅＳＩＭ保持の確認 前回MR→最新MRへのGOTA確認 ※モバイルネットワーク使用 | B30: 19 | C30: OTR-MA-LQC-999.002.003 | D30: FinalTest - Software Update(FOTA/GOTA) | E30: n-1 -> n | F30: User data retention verification : eSIM registration information | G30: a．「OTR-MA-LQC-999.002.001」と同時に実施すること 前回MRソフトにしておく (1) GOTA前にeSIMを有効にしておく Wi-FiをOFFにしておく(モバイルネットワークを使用するため) | H30: (2) 最新MRソフトへGOTAする (3) GOTA後、手順1で設定したeSIM情報が保持されているか確認する | I30: ・GOTA後、eSIM情報が保持されていること | J30: =IFERROR(HLOOKUP($K$3,$Z$11:$AI$65,$X30+1,FALSE),"自動入力") -> 自動入力 | L30: {=_xlfn.IFS($K$3="","自動入力",COUNTIF(J30:J31,"×")=COUNTA(J30:J31),"試験不可",COUNTIF(J30:J31,"〇")=COUNTA(K30:K31),IF(COUNTIF(K30:K31,"試験不可")=COUNTA(K30:K31),"試験不可",IF(COUNTIF(K30:K31,"失敗")>0,"NG","OK")),TRUE,"")} -> 自動入力 | N30: =IF(COUNTIF(J30:J31,"×")=COUNTA(J30:J31),"機能が無い為。",IF(AND(COUNTIF(J30:J31,"〇")>0,$S$30=""),"ジャンプ可能なソフトが無い為。","")) | R30: =Q30-P30 -> 0 | S30: =IF($T$6<>"",$T$6,"") | T30: ＜準備＞ ①ダウンロードツールにて前回MRへFULL_DL ②リブート後、電源オフしてDNANDLoaderでUSB有効化 ※「SUCCESS」表示後に電源オフの場合は電源オンしてください ③待ち受け画面まで設定をして下さい(別ワークシート参照） pSIMを入れていると初期設定画面でSIMの選択画面になりますので、下の表示(こちらがeSIM)をデータ通信・通話・SMSで選択してください。 ④アプリを最新にします。 Playストア→右上アカウントアイコンタップ→アプリとデバイスの管理(マイアプり＆ゲーム)→アップデート利用可能の「すべて更新」タップ→「詳細を表示」→全てのアプリが更新されるのを暫く待ちます ⑤GOTA組み合わせ：前回MR⇒最新MR ⑥モバイルネットワーク使用(WiFiオフしてください） ⑦eSIMを優先SIM設定(データ通信、通話、SMS使用） 設定→ネットワークとインターネット→デュアルSIM設定→優先SIMがeSIMになっている事を確認 ⑧＋メッセージの初期設定をしておいて下さい。 ⑨No20の動作確認をGOTA前に実施してください。(音声通話・データ通信・SMS受信) ＜手順＞ ①GOTA前のeSIM設定確認 設定→デバイス情報→電話番号(SIMスロット2)をタップ→背面のQRコードラベルと同じ電話番号が表示される事を確認 ②アップデート 設定→システム→システムアップデート→システムアップデート利用可能の画面で【更新内容】のビルド番号が最新MRの番号である事を確認→ダウンロードしてインストール→モバイルネットワークを使用をタップ→アップデートが完了するまで暫く待ちます。(10分程度)→今すぐ再起動をタップ ③電源オフとしてDNANDLoaderでUSBデバッグオンを設定 ④GOTA後のeSIM設定確認 設定→デバイス情報→電話番号(SIMスロット2)をタップ→背面のQRコードラベルと同じ電話番号が表示される事を確認 ⑤No20をGOTA後に確認する | U30: ＜ツール＞ ①ブタ ②adbtool ③Vysor(スクショとミラキャスト）or adb_capture.bat 【注意事項】 ①アップデートが正常に終了しない場合や、極端に時間が長い場合は松井まで連絡してください。 ②OSVの場合は自動的にダウンロードが開始されない(ソフトウェア更新通知→ユーザー操後にダウンロード開始） ※モデルによって異なりますが、通知エリア(Nortification)に通知されるので、それからユーザー操作でダウンロードする ＜待ち受け後にデュアルSIM設定を変える場合＞ | X30: =X29+1 -> 19 | Y30: =MAX(X30:X31)-X29 -> 2 | Z30: 〇 | AA30: 〇 | AB30: 〇 | AD30: 〇 | AE30: 〇 | AT30: ＜SIM設定＞ ※eSIMを通話/SMS/データ通信様に設定します。 ＜ｐSIM設定をオン設定＞ 設定→ネットワークとインターネット→pSIM選択→このSIMを使用する→オフ ※eSIMのモバイルデータがオンになっている事を確認してください。オフの場合はオンにしてください。 ＜eSIM設定をオン設定＞ 設定→ネットワークとインターネット→eSIM選択→通話の設定→eSIM選択→SMSの設定→eSIM選択→モバイルデータを自動に切替→on ＜その他＞ WiFi接続をオフにする | AV30: ・eSIM設定方法について教えて頂けますか？ ※プロファイルの依頼等も含めて… | AW30: ＜eSIM＞ 横浜で対応して頂けますが、SBからQRコードを発行して貰い設定します。一度設定したら消去はしませんので、その端末は本試験に使い続ける必要があります。【注意】ファクトリリセット時にeSIM消去を行わない様に注意が必要です。
B31: 20 | H31: (4) 音声通話、SMS送受信、データ通信(ブラウザでWebサイトを表示するなど)を確認する | I31: ・eSIMで音声通話、SMS送受信、データ通信(ブラウザでWebサイトを表示するなど)ができること | J31: =IFERROR(HLOOKUP($K$3,$Z$11:$AI$65,$X31+1,FALSE),"自動入力") -> 自動入力 | R31: =Q31-P31 -> 0 | T31: ＜準備＞ ※対抗機 ①前回MRのソフトバージョンにFull_DLを行って待ち受けまで設定を試験機と同様に行う ②対抗機はpSIMのみで良いので、キャリアSIM(SB or YM）を入れて下さい ③アプリを最新にします。 Playストア→右上アカウントアイコンタップ→アプリとデバイスの管理→アップデート利用可能の「すべて更新」タップ→「詳細を表示」→全てのアプリが更新されるのを暫く待ちます ④＋メッセージの初期設定をしておいて下さい。 ＜手順＞ ※試験機 ●音声通話 試験機→対抗機、対抗機→試験機へ発信して通話確認 ●SMS送受信 ＋メッセージアプリで、試験機⇔対抗機にテキストデータ、画像(例えばカメラで取得した画像)の送受信を行う ※GOTA後にテキストデータと画像が消えていない事を確認 ●データ通信 Chrome⇒アカウント選択が聞かれた場合は設定したアカウントを選択⇒web検索が正常に行える事を確認(タップして画面遷移する事を確認⇒画像データがある画面で画像をロングタップして「画像をダウンロード」を選択→ダウンロードした画像を開いて確認 ※GOTA後にダウンロードした画像が消えていない事を確認 (Filesアプリ→ダウンロード⇒ダウンロードした画像が残っている事を確認 | X31: =X30+1 -> 20 | Z31: 〇 | AA31: 〇 | AB31: 〇 | AD31: 〇 | AE31: 〇 | AT31: ※設定→ネットワークとインターネット→SIM⇒eSIM⇒このSIMを使用する⇒オン設定 ⇒上記後に、設定⇒デバイス情報⇒電話番号(SIMスロット2)の電話番号が表示されている事を確認 ※ダウンロードは必ず「モバイルネットワークを使用」で実施してください。 (eSIMを使用します。pSIMはオフ設定でお願いします) ※SIMの選択は通話・SMS・インターネット共にeSIMになっている事を確認してからDL後の確認をお願い致します。
A32: WiFi接続でのGOTA確認 前回MR→最新MRへのGOTA確認 ※WiFi接続 | B32: 21 | C32: OTR-MA-LQC-999.002.009 | D32: FinalTest - Software Update(FOTA/GOTA) | E32: n-1 -> n | F32: Verification of retained settings : Roaming/Mobile data communication/緊急速報メール(Wireless emergency alerts) | G32: a．「OTR-MA-LQC-999.002.001」と同時に実施すること 前回MRソフトにしておく Wi-Fi APへ接続しておく (1) GOTA前に下記を設定する ・ローミング：OFF ・モバイルデータ：OFF ・緊急速報メール：配下の設定項目をすべて有効にする | H32: (2) 最新MRへGOTAする (3) GOTA後、手順1で設定したものが保持されているか確認する | I32: ・GOTA後、設定したものが保持されていること | J32: =IFERROR(HLOOKUP($K$3,$Z$11:$AI$65,$X32+1,FALSE),"自動入力") -> 自動入力 | L32: {=_xlfn.IFS($K$3="","自動入力",COUNTIF(J32,"×")=COUNTA(J32),"試験不可",COUNTIF(J32,"〇")=COUNTA(K32),IF(COUNTIF(K32,"試験不可")=COUNTA(K32),"試験不可",IF(COUNTIF(K32,"失敗")>0,"NG","OK")),TRUE,"")} -> 自動入力 | N32: =IF(COUNTIF(J32,"×")=COUNTA(J32),"機能が無い為。",IF(AND(COUNTIF(J32,"〇")>0,$S$32=""),"ジャンプ可能なソフトが無い為。","")) | R32: =Q32-P32 -> 0 | S32: =IF($T$6<>"",$T$6,"") | T32: ＜準備＞ ①ダウンロードツールにて前回MRへFULL_DL ②リブート後、電源オフしてDNANDLoaderでUSB有効化 ※「SUCCESS」表示後に電源オフの場合は電源オンしてください ③待ち受け画面まで設定をして下さい(「待ち受け設定」シート参照） pSIMを入れていると初期設定画面でSIMの選択画面になりますので、上の表示(こちらがpSIM)をデータ通信・通話・SMSで選択してください。 ④GOTA組み合わせ:前回MR⇒最新MR ⑤WiFiのAPを使用(モバイルネットワークは使用しません） ⑥下記を設定 ・設定⇒ネットワークとインターネット⇒SIM⇒SB⇒ローミング：OFF・モバイルデータ：OFF ・設定⇒安全性と緊急情報⇒緊急速報メール⇒メッセージ受信を再通知する：1回・常に最大音量で通知音を鳴らす：on(デフォルト） ・バイブレーションはグレイアウトしてることを確認。 ＜手順＞ ①アップデート 設定→システム→システムアップデート→システムアップデート利用可能の画面で【更新内容】のビルド番号が最新MRの番号である事を確認→ダウンロードしてインストール→アップデートが完了するまで暫く待ちます。(10分程度)→今すぐ再起動をタップ ②上記の⑥の設定が保持されている事を確認 | X32: =X31+1 -> 21 | Y32: =MAX(X32)-X31 -> 1 | Z32: 〇 | AA32: 〇 | AB32: 〇 | AD32: 〇 | AE32: 〇 | AT32: ※5.203YO.0350.a → 5.212YO.0356.a ( MR20 → MR21 ) ※WiFiは5GのAPへ接続 ※DL後はアプリを最新版に更新しておいてください(メールが古いと送受信できません）（20分程度） ①前回MRへ再DL：3分 ②再起動：1分 ③初期設定：3分 ④設定⇒ネットワークとインターネット⇒SIM⇒YM⇒ローミング：OFF・モバイルデータ：OFF ⑤設定⇒安全性と緊急情報⇒緊急速報メール⇒メッセージ受信を再通知する：1回・常に最大音量で通知音を鳴らす：on(デフォルト） ※バイブレーションはグレイアウトしています。 ④MR20⇒MR21へアップデート ： WiFi接続(5G)で実施 ：135MB ：6分 ④再起動 ：2分 | AU32: 緊急速報メール：配下の設定項目をすべて有効にする設定はAndroidのバージョンなどで違いがありますので、タップしてすべてチェックしてください
A33: 2回前のMRソフト→最新MRへのGOTA確認(ルートA) ※Redmineにて差分作成が行われていない場合は実施しない ※モバイルネットワーク使用 | B33: 36 | C33: OTR-MA-LQC-999.003.001 | D33: FinalTest - Software Update(FOTA/GOTA) | E33: Jump Up | F33: Update confirmation | G33: a．下記のソフトVer.にてGOTAを行う ルートA：x回前のMRソフト→最新MRソフト ルートB：2回前のMRソフト→最新MRソフト ※ルートA端末：x回前＝商用リリースソフトのうち、最新MRソフトへJumpUp可能な最も古いソフト (※古いOSからGOTA可能な場合があるため注意すること) ※ルートB端末：2回前＝最新MRソフトの2回前の商用リリースソフト ※2回前のMRソフトからのJumpUp非対応の場合、JumpUp可能な最新Ver.で試験すること b．GOTA前のソフトVer.が正しいことを確認する ※ソフトVer.とIMEIのScreenShotを取得する c．Wi-FiをOFFにしておく(モバイルネットワークを使用するため) | H33: (1) 各ルートごとに最新MRへGOTAする (2) ソフトVer.とIMEIのScreenShotを取得する | I33: ・エラーなくGOTAできること ・OSVの場合は自動的にダウンロードが開始されないこと(ソフトウェア更新の通知＞ユーザー操作後にダウンロードが開始されること) ・GOTA後にソフトVer.が更新したいVer.となっていること ・GOTA前後に取得したソフトVer.とIMEIのScreenShotを提出すること | J33: =IFERROR(HLOOKUP($K$3,$Z$11:$AI$65,$X33+1,FALSE),"自動入力") -> 自動入力 | L33: {=_xlfn.IFS($K$3="","自動入力",COUNTIF(J33:J34,"×")=COUNTA(J33:J34),"試験不可",COUNTIF(J33:J34,"〇")=COUNTA(K33:K34),IF(COUNTIF(K33:K34,"試験不可")=COUNTA(K33:K34),"試験不可",IF(COUNTIF(K33:K34,"失敗")>0,"NG","OK")),TRUE,"")} -> 自動入力 | N33: =IF(COUNTIF(J33:J34,"×")=COUNTA(J33:J34),"機能が無い為。",IF(AND(COUNTIF(J33:J34,"〇")>0,$S$33=""),"ジャンプ可能なソフトが無い為。","")) | O33: 〇 | R33: =Q33-P33 -> 0 | S33: =IF($T$5<>"",$T$5,"") | T33: ＜準備＞ ①ダウンロードツールにて2回前MRへFULL_DL ②リブート後、電源オフしてDNANDLoaderでUSB有効化 ※「SUCCESS」表示後に電源オフの場合は電源オンしてください ③待ち受け画面まで設定をして下さい pSIMを入れていると初期設定画面でSIMの選択画面になりますので、上の表示(こちらがpSIM)をデータ通信・通話・SMSで選択してください。 ④GOTA組み合わせ：2回前MR⇒最新MR ⑤モバイルネットワーク使用(WiFiオフしてください） ⑥pSIMを優先SIM設定(データ通信、通話、SMS使用） 設定→ネットワークとインターネット→デュアルSIM設定→優先SIMがSIM1になっている事を確認 ⑦アプリを最新にします。 Playストア→右上アカウントアイコンタップ→アプリとデバイスの管理→アップデート利用可能の「すべて更新」タップ→「詳細を表示」→全てのアプリが更新されるのを暫く待ちます ⑧＋メッセージの初期設定をしておいて下さい。 ＜手順＞ ①GOTA前スクショ 設定→デバイス情報→IMEI1/2とビルド番号 ※1枚に入らない時は2枚に分ける ②GOTA前にNo37～No42の設定と確認を行う ③アップデート 設定→システム→システムアップデート→システムアップデート利用可能の画面で【更新内容】のビルド番号が最新MRの番号である事を確認→ダウンロードしてインストール→モバイルネットワークを使用をタップ→アップデートが完了するまで暫く待ちます。(10分程度)→今すぐ再起動をタップ ④電源オフしてDNANDLoaderでUSBデバッグオンを設定 ⑤GOTA後スクショ 設定→デバイス情報→IMEI1/2とビルド番号 ※1枚に入らない時は2枚に分ける ⑥GOTA前後の画像をWinMergeで比較して差を確認してください。詳しくは別シートを参照下さい ⑦GOTA後のNo37～No42の確認を行って下さい | X33: =X60+1 -> 36 | Y33: =MAX(X33:X34)-X60 -> 2 | Z33: 〇 | AA33: 〇 | AB33: 〇 | AD33: 〇 | AE33: 〇 | AT33: ※3.191YO.0261.a → 5.212YO.0356.a ( MR19 → MR21 ) ※WiFi接続無し ※DL後はアプリを最新版に更新しておいてください(メールが古いと送受信できません）(20分程度） ①2回前MRへ再DL：3分 ②再起動：1分 ③初期設定：3分 ④MR19⇒MR21へアップデート ： 4Gで実施 ：2.19GB ：19分 ④再起動 ：2分 | AU33: JumpUp可能なソフトがない為
B34: 37 | H34: (3) GOTA後、音声発信、音声着信、SMS送信、SMS受信、データ通信(ブラウザでWebサイトを表示するなど)を行う | I34: ・GOTA後、データ通信が正常に動作することを確認すること ・音声発信、音声着信、SMS送信、SMS受信に問題がないこと | J34: =IFERROR(HLOOKUP($K$3,$Z$11:$AI$65,$X34+1,FALSE),"自動入力") -> 自動入力 | R34: =Q34-P34 -> 0 | T34: ＜手順＞ ●音声通話 試験機→対抗機、対抗機→試験機へ発信して通話確認 ●SMS送受信 ＋メッセージアプリで、試験機⇔対抗機にテキストデータ、画像(例えばカメラで取得した画像)の送受信を行う ※GOTA後にテキストデータと画像が消えていない事を確認 ●データ通信 Chrome⇒アカウント選択が聞かれた場合は設定したアカウントを選択⇒ブラウジングが正常に行える事を確認(タップして画面遷移する事を確認 | X34: =X33+1 -> 37 | Z34: 〇 | AA34: 〇 | AB34: 〇 | AD34: 〇 | AE34: 〇 | AT34: ※GOTA後に確認する | AU34: JumpUp可能なソフトがない為
B35: 38 | C35: OTR-MA-LQC-999.003.002 | D35: FinalTest - Software Update(FOTA/GOTA) | E35: Jump Up | F35: User data retention verification : Data saved in storage/application. | G35: a．「OTR-MA-LQC-999.003.001」と同時に実施すること (1) GOTA前に、下記のデータを用意する ※各データは複数個を用意し、使用したデータを試験結果に記録 すること ・電話帳：入力可能なフィールドをすべて入力すること ・画像(カメラ撮影、ダウンロード) ・LINEのトーク履歴 ・メール：送信SMS、受信SMS、送信MMS、受信MMS | H35: (2) 最新MRソフトへGOTAする (3) GOTA後、手順1で用意したデータが保持されているか確認する | I35: ・GOTA後、用意したデータが保持されていること | J35: =IFERROR(HLOOKUP($K$3,$Z$11:$AI$65,$X35+1,FALSE),"自動入力") -> 自動入力 | L35: {=_xlfn.IFS($K$3="","自動入力",COUNTIF(J35,"×")=COUNTA(J35),"試験不可",COUNTIF(J35,"〇")=COUNTA(K35),IF(COUNTIF(K35,"試験不可")=COUNTA(K35),"試験不可",IF(COUNTIF(K35,"失敗")>0,"NG","OK")),TRUE,"")} -> 自動入力 | N35: =IF(COUNTIF(J35,"×")=COUNTA(J35),"機能が無い為。",IF(AND(COUNTIF(J35,"〇")>0,$S$33=""),"ジャンプ可能なソフトが無い為。","")) | R35: =Q35-P35 -> 0 | T35: ＜手順＞ ※各データは2個以上用意する ※GOTA後は動作確認は不要で、電話帳・画像・LINEトーク・SMSが消えていない事を確認してください。 ●電話帳登録 「電話帳登録」ワークシート参照 ●画像(カメラ撮影、ダウンロード) ・カメラで2枚以上撮影 フォトアプリで画像確認 ・ダウンロード ブラウザ(Chrome)⇒適当なサイトに飛ぶ⇒「画像」をタップ(上の方)⇒画像をロングタップして「画像をダウンロード」 Filesアプリで画像を確認 ●LINEトーク ・【LINEトーク設定方法】でアプリを設定 ・対抗機とラインメッセージ(テキスト、画像)の送受信実施(2回以上） ●メール(プラスメッセージ） No37と同じなので実施不要です | U35: 【LINEトーク設定方法】 ①PlayストアからLINEをインストール ②「新規登録」⇒「次へ」⇒許可⇒認証を行ってくださいで自分の電話番号を確認⇒「⇒」⇒「OK」⇒認証番号を確認⇒「許可」⇒「いいえ、ちがいます」⇒「次へ」⇒「アカウントを新規作成⇒アカウントを新規登録で名前を登録(例：試験機）⇒「⇒」⇒パスワードを登録(例：QAkitami123123）⇒「⇒」⇒友達追加設定のチェックボックスを全て外す⇒「⇒」⇒年齢確認「あとで」⇒「同意する」⇒「OK」⇒「アプリの使用時のみ」⇒「許可」⇒「閉じる」(バッテリー…のポップアップ）⇒友達…のポップアップ「キャンセル」⇒「設定に移動→「許可」⇒対抗機と試験機の友達追加をしてください。 | X35: =X34+1 -> 38 | Y35: =MAX(X35)-X34 -> 1 | Z35: 〇 | AA35: 〇 | AB35: 〇 | AD35: 〇 | AE35: 〇 | AT35: ※GOTA後に確認する | AU35: JumpUp可能なソフトがない為
B36: 39 | C36: OTR-MA-LQC-999.003.004 | D36: FinalTest - Software Update(FOTA/GOTA) | E36: Jump Up | F36: User data retention verification : Screen lock/Biometric authentication setting | G36: a．「OTR-MA-LQC-999.003.001」と同時に実施すること (1) GOTA前に下記を設定する ・画面ロック：パターン、PIN、パスワードのいずれか(備考へ記載すること) ・生体認証：指紋認証 (対応機種のみ) ・生体認証：顔認証 (対応機種のみ) | H36: (2) 最新MRソフトへGOTAする (3) GOTA後、設定アプリを起動し、手順1で設定したものが保持されているか確認する | I36: ・GOTA後、設定したものが保持されていること | J36: =IFERROR(HLOOKUP($K$3,$Z$11:$AI$65,$X36+1,FALSE),"自動入力") -> 自動入力 | L36: {=_xlfn.IFS($K$3="","自動入力",COUNTIF(J36:J39,"×")=COUNTA(J36:J39),"試験不可",COUNTIF(J36:J39,"〇")=COUNTA(K36:K39),IF(COUNTIF(K36:K39,"試験不可")=COUNTA(K36:K39),"試験不可",IF(COUNTIF(K36:K39,"失敗")>0,"NG","OK")),TRUE,"")} -> 自動入力 | N36: =IF(COUNTIF(J36:J39,"×")=COUNTA(J36:J39),"機能が無い為。",IF(AND(COUNTIF(J36:J39,"〇")>0,$S$33=""),"ジャンプ可能なソフトが無い為。","")) | R36: =Q36-P36 -> 0 | T36: ＜手順＞ ※GOTA後は、画面ロック・生体認証設定が保持されている事を動作確認してください。(No40～42を実施) ●画面ロック ※パターン、PIN、パスワードの何れかを備考欄へ記載する事 【注記】パターンの場合は「Ｚ」、 パスワードの場合は「１２３４」 設定⇒セキュリティとプライバシー⇒画面ロックを設定⇒例：パターン⇒Ｚ⇒次へ⇒Ｚ⇒確認⇒完了 ●生体認証(顔認証) 設定⇒セキュリティとプライバシー⇒デバイスのロック解除⇒顔認証と指紋認証によるロック解除⇒Z⇒同意する⇒スタート⇒カメラ起動⇒完了 ●生体認証(指紋認証) 設定⇒セキュリティとプライバシー⇒デバイスのロック解除⇒顔認証と指紋認証によるロック解除⇒Z⇒指紋⇒もっと見る⇒同意する⇒センサーを指でタッチ⇒20回タッチ⇒完了 | U36: 【注意】 ●生体認証はカメラが無い場合や、指紋認証の機能が無い場合がありますので、その時は実施しなくても良いです。 | X36: =X35+1 -> 39 | Y36: =MAX(X36:X39)-X35 -> 4 | Z36: 〇 | AA36: 〇 | AB36: 〇 | AD36: 〇 | AE36: 〇 | AT36: ①設定→セキュリティとプライバシー⇒各種ロックを設定 ・画面ロック パターン(Ｚパターン） ・顔認証セットアップ ・指紋の設定セットアップ ※5分 | AU36: JumpUp可能なソフトがない為
B37: 40 | H37: (4) ロック画面に切り替え、手順(1)で設定した画面ロックパターン、PIN、またはパスワードの認識により、ロックを解除する | I37: ・(4)で、解除のパターン、PIN、パスワードの入力により、画面ロックを解除できること | J37: =IFERROR(HLOOKUP($K$3,$Z$11:$AI$65,$X37+1,FALSE),"自動入力") -> 自動入力 | R37: =Q37-P37 -> 0 | T37: ＜手順＞ ①省電力画面(黒画面) ②電源キー単押し ③画面タップ ④パターンロック画面で「Z」入力 ⑤待ち受け画面へ遷移する事 ※顔が端末正面に来ない様に操作してください。(顔認証で解除される) | X37: =X36+1 -> 40 | Z37: 〇 | AA37: 〇 | AB37: 〇 | AD37: 〇 | AE37: 〇 | AT37: ※GOTA後に確認する | AU37: JumpUp可能なソフトがない為
B38: 41 | H38: (5) ロック画面へ戻り、手順(1)で設定した指紋認証または顔認証 でロックを解除する | I38: ・(5)で、指紋認証と顔認証 により、画面ロックを解除できること | J38: =IFERROR(HLOOKUP($K$3,$Z$11:$AI$65,$X38+1,FALSE),"自動入力") -> 自動入力 | R38: =Q38-P38 -> 0 | T38: ＜手順＞ ①省電力画面(黒画面) ②電源キー単押し ③ロック画面で指紋登録した指でタップ ④待ち受け画面へ遷移する事 ※顔が端末正面に来ない様に操作してください。(顔認証で解除される) | X38: =X37+1 -> 41 | Z38: × | AA38: 〇 | AB38: 〇 | AD38: × | AE38: 〇 | AT38: ※GOTA後に確認する | AU38: JumpUp可能なソフトがない為
B39: 42 | H39: (6) ロック画面へ戻り、手順(1)で設定した顔認証でロックを解除する | I39: ・(6)で、顔認証により、画面ロックを解除できること | J39: =IFERROR(HLOOKUP($K$3,$Z$11:$AI$65,$X39+1,FALSE),"自動入力") -> 自動入力 | R39: =Q39-P39 -> 0 | T39: ＜手順＞ ①省電力画面(黒画面) ②電源キー単押し ③ロック画面で顔を正面へ ④待ち受け画面へ遷移する事 | X39: =X38+1 -> 42 | Z39: 〇 | AA39: 〇 | AB39: 〇 | AD39: 〇 | AE39: 〇 | AT39: ※GOTA後に確認する | AU39: JumpUp可能なソフトがない為
B40: 43 | C40: OTR-MA-LQC-999.003.005 | D40: FinalTest - Software Update(FOTA/GOTA) | E40: Jump Up | F40: User data retention verification : Emergency Information/Emergency Contact | G40: a．「OTR-MA-LQC-999.003.001」と同時に実施すること b．画面ロックを設定する ※パターン、PIN、パスワードのいずれか c．対向機を用意し、対向機の電話番号を電話帳に登録する (1) GOTA前に下記を設定する ・医療に関する情報：入力可能なフィールドをすべて入力すること ・緊急SOS：緊急SOS、「緊急サービスへの発信」をONに設定し、「通報用の電話番号」へ対向機の電話番号を登録する ・緊急連絡先：対向機の電話番号を追加する | H40: (2) 最新MRソフトへGOTAする (3) GOTA後、手順1で設定したものが保持されているか確認する | I40: ・手順3で、設定したものが保持されていること | J40: =IFERROR(HLOOKUP($K$3,$Z$11:$AI$65,$X40+1,FALSE),"自動入力") -> 自動入力 | L40: {=_xlfn.IFS($K$3="","自動入力",COUNTIF(J40:J42,"×")=COUNTA(J40:J42),"試験不可",COUNTIF(J40:J42,"〇")=COUNTA(K40:K42),IF(COUNTIF(K40:K42,"試験不可")=COUNTA(K40:K42),"試験不可",IF(COUNTIF(K40:K42,"失敗")>0,"NG","OK")),TRUE,"")} -> 自動入力 | N40: =IF(COUNTIF(J40:J42,"×")=COUNTA(J40:J42),"機能が無い為。",IF(AND(COUNTIF(J40:J42,"〇")>0,$S$33=""),"ジャンプ可能なソフトが無い為。","")) | R40: =Q40-P40 -> 0 | T40: ＜手順＞ ※GOTA後は、①の設定が保持されている事と緊急SOSは動作確認(No44 ～45)してください。 ①設定→安全性と緊急情報→医療に関する情報→各情報を全て設定 ②設定→安全性と緊急情報→緊急SOS→緊急通報→緊急通報用の電話番号を110番から必ず変更してください。(例えば自分の業務端末等) ※右記の＜緊急通報用の電話番号設定の初期設定時の手順＞を参照してください。 ※1回変更するとGoogleアカウントに紐づくので以降の変更は要りませんが、試験前に必ず確認してください。 | U40: 【注記】 緊急通報用の電話番号のデフォルトは「１１０」番です。 デフォルト設定を変える前に発信しない様に発信前に必ず電話番号が１１０番では無い事を確認してください。 ＜緊急通報用の電話番号設定の初期設定時の手順＞ 設定→安全性と緊急情報→緊急SOS→緊急通報サービスへの発信→通報用の電話番号→その他→自分の業務端末→完了 | X40: =X39+1 -> 43 | Y40: =MAX(X40:X42)-X39 -> 3 | Z40: 〇 | AA40: 〇 | AB40: 〇 | AD40: 〇 | AE40: 〇 | AT40: ①設定→安全性と緊急情報→医療に関する情報→各情報を全て設定 ②設定→安全性と緊急情報→緊急SOS→緊急通報→緊急通報用の電話番号を110番から必ず変更してください。(例えば自分の業務端末等) ※1回変更するとGoogleアカウントに紐づくので以降の変更は要りませんが、試験前に必ず確認してください。 | AU40: JumpUp可能なソフトがない為
B41: 44 | H41: (4) 電源ボタンをすばやく5回押し、緊急SOSを開始する | I41: ・手順4で、緊急SOSとして登録した対向機へ緊急発信できること | J41: =IFERROR(HLOOKUP($K$3,$Z$11:$AI$65,$X41+1,FALSE),"自動入力") -> 自動入力 | R41: =Q41-P41 -> 0 | T41: ＜手順＞ ※緊急通報用の電話番号が110番から変更されている事を確認する事 ①省電力画面から素早く5回電源キー押下で緊急呼発信画面へ遷移して3秒長押しで発信出来る事を確認 | X41: =X40+1 -> 44 | Z41: 〇 | AA41: 〇 | AB41: 〇 | AD41: 〇 | AE41: 〇 | AT41: ※GOTA後に確認する | AU41: JumpUp可能なソフトがない為
...

Sheet 待ち受け設定
B2: 【待ち受け設定方法】
B4: 1）必要なツール
B6: ①adbtool ※adbコマンドを半自動で端末に入力できるツール
B7: ②Vysor ※画面をPCと共有できるツール(スクショで使用します)
B8: ③WinMerge ※画像比較ツール(スクショした二つの画面を比較します)
B10: ＜入手先＞
B11: 下記から入手してください。
C13: Tools
B16: 2)手順
B17: ①adbtool
B18: ・ツールを立ち上げると右の画面になり「接続中のデバイス：＊＊＊＊＊…」と緑の文字になっている事を確認してください。
B19: ※赤の場合はUSBデバッグオンが失敗しているので、MTKの場合は「MTKモデル」シートのUSBデバッグオン方法をもう一度試して下さい。
B20: ・共通の赤枠部分が使用するコマンドです。
B21: どれを使うかは下記で説明していきます。
B52: ②Vysor
B53: ・インストールしたらVysorアイコン(目)をクリックしてツールを立ち上げて下さい。
B75: 3）待ち受け設定方法
S137: ※電話番号でpSIM/eSIM判別

Sheet MTKモデル
B2: 【MediaTekモデルの場合】
B5: 1）USBデバッグオン方法
B7: ①必要なツール
B9: 「DNANDLoader」というツールを使います。
B10: 保存場所は下記になります。
B11: モデルによって準備しなければなりませんので、もし下記に無い場合は技術：松本文明さんに依頼してください。
B12: 「＊＊＊＊モデルのUSBデバッグ有効化のDnandloaderをお願いしたいです」と依頼してください。
C14: adb有効化(MTK)
B17: ②準備(EB1146の場合)
B18: フォルダの中身は下記になっておりますので、「.exe」ファイルをダブルクリックするとツールが立ち上がります。
B37: ③使い方
B38: ・端末は電源オフ状態です
B39: ・ツールの「LoadDNAND」をクリックしてください
B40: ・端末をUSBケーブル経由でPCにつないでください(60秒位でタイムアウトします)
B41: ・下記の画面が出たら成功です。端末の電源をオン状態にしてください。(ツールによっては勝手に立ち上がってきます)
B42: 失敗した場合(Faild表示)、OKを押して「LoadDNAND」のクリックから行って下さい。
C44: ＜成功した場合＞
B53: ※ツールは立ち上げっぱなしでも問題ありません。

Sheet Qualcommモデル
B2: 【Qualcommモデルの場合】
B4: QualcommとMediaTekの違いは使用するツールが異なります。
B5: ・MediaTek ： DNANDLoader/KCFlashTool
B6: ・Qualcomm：切替ツール_auto.bat/ADBCommand_Enable_and_DropFlag_v3.1K(工程管理無し).bat/ダウンロードは各モデルのFBローダーを使ってください。(リンク先は下記）
B9: 1）必要なツール
B11: ①モード切替ツール
B12: 端末のCOM(USBで接続した時のパソコンでの認識）を認識させる為に、下記のツールを使用します。
B13: 使い方は、リンクから自分のPCにコピペして、「切替ツール_auto.bat」をダブルクリックします。
C15: Mode切替
B31: ②USBデバッグオン
B32: ビルド番号を7回タップして、システムからUSBデバッグオンをしなくても、電源オン中にUSBデバッグオンにする方法があります。(MTKのDNANDLoaderのQualcomm版です）
C34: adb有効化(Qualcomm)
C35: ※①のモード切替ツールを立ち上げておいてください。
C36: ※フォルダごと自分のPCにコピペしてZIPファイルを解凍しておいてください。
C39: ＜使い方＞
C40: ①端末を電源オンします。
C41: ②「ADBCommand_Enable_and_DropFlag_v3.1K(工程管理無し).bat」をダブルクリックして下さい。(右図）
C42: 【注記】リトライは20回までなのでもしNGになったら①からやり直して下さい。
C43: ③一旦、端末が再起動して、コンソールにOKがでたら準備OKです。
C44: ④端末が起動している事を確認してください。(下図)
C45: ⑤ツールを閉じるときは「ｑ」(小文字)を押すか「×」で閉じて下さい。
C46: 続ける場合は、何か適当なキー(enterで良いです)を押すと①の状態になります。
B65: ③ダウンロードツール
B66: 下記のURLにモデル毎のダウンロードツールが保存されております。
C68: Box\Softsource01\SoftSourceAct\release\TOOLS\DL
C70: ＜例：EB1083の場合は、下記の様にFBLoaderが保存されておりますので自分のPCにコピペしてください＞

Sheet WinMerge画像比較
B2: 【WinMerge画像比較方法】
B4: 1）アプリの入手方法
B5: アプリは下記から自分のPCにコピペして「WinMerge-2.16.50-jp-4-x64-Setup.exe」を実行してインストールして下さい。
C7: WinMerge
M9: ※画像マッチングをおこなっており、違う所は「黄色塗りつぶし」になります。
M29: ※この例では技術基準適合証明書の比較ですが、ポップアップ内に黄色い塗りつぶしは無いので差異は無しになります。
C41: 【注記】画像が少しでもズレると下記の例の様に全滅になります。この場合はどうしようも無いので、確認したいところを目視で確認してください。
C42: ※Geminiを使っても良いですが、文字比較を行うのですが、ご認識する場合があるので、目視で見るのが一番良いと思います。

Sheet 電話帳登録
B2: ＜本体に電話帳を登録する方法＞
B3: ※Googleアカウントには登録しないでください。
B5: EB1146の事例で説明していきます。
B7: ＜事前準備＞
B8: 「phone_number.vcf」というファイルの入ったSDカードを準備してあります。(保管場所は非課金SIMが入っている施錠BOXです）
B9: SDカードを本体に装着して、以下の手順に従ってSDカード内のデータ(3個入っています)を本体にインポートしてください。
J12: ↓Googleアカウントは未設定の時は出ません(強制的に本体に保管されます) | R12: ※放っておく… | V12: ※Googleアカウントと同期しないでください
F42: ※Googleアカウントには保存されていない確認 | N42: ※本体に登録された3つの電話帳 | R42: ※同期をタップしないでください

Sheet 非課金SIMサイト
B2: ■データ量の確認方法
B4: 試験の中で非課金SIMを使った試験では、下記のWEBサイトでデータ量を確認する必要がありますので、そのアクセス方法について記載します。
B6: <MySoftBank＞
B8: ■ログインURL
B9: ログイン | My SoftBank | ソフトバンク
B11: 電話番号 | C11: 07050787161
B12: パスワード | C12: kyocera_qaeg_123
B14: ■データ使用量
B33: <MyYM＞
B35: ■ログインURL
B36: ログイン | ワイモバイル
B38: 電話番号 | C38: 07065644350
B39: パスワード | C39: kyocera_qaeg_123
B41: ■データ使用量

Sheet 修正課題
B2: 1 | C2: Qualcommモデル対応の手順追加 ※ツールの使い方やMTKとの手順の差異
B3: 2 | C3: 画像判定の方法 → WinMergeを使用する ※複数枚になる場合はマッチング精度が落ちる
B4: 3 | C4: 手順書と注意事項欄の整理
B5: 4 | C5: 技術記載列の非表示化 ※使っていないので必要に応じて表示する様にする
B6: 5 | C6: 「ｘ回前」の行の入れ替え ※番号はそのままにするかな？
B7: 6 | C7: 共通内容は別ワークシートにして、そこを参照する様に修正するかな？ 例えば非課金SIMのデータ容量の見方とかを別ワークシートにして分かりやすくする。 ※手順の文書が長い…
B8: 7 | C8: マスターファイル等のリンク先を別ワークシートにまとめる
B9: 8 | C9: 電話帳登録は本体に手入力しているが、vcfファイルからインポートして実施する様に手順を変更。
B10: 9 | C10: 技術基準適合証明書のスクショは他の試験と一緒にする
B11: 10
B12: 11
B13: 12
B14: 13
B15: 14
B16: 15

Sheet リンク
B3: 【マスターファイル】
B5: 試験書
